{
    "id": "LUCENE-1992",
    "title": "intermittent failure in TestIndexWriter. testExceptionDuringSync",
    "details": {
        "labels": "",
        "priority": "Minor",
        "components": [
            "core/index"
        ],
        "type": "Bug",
        "fix_versions": [
            "2.9.1",
            "3.0"
        ],
        "affect_versions": "None",
        "resolution": "Fixed",
        "status": "Closed"
    },
    "description": "common.test:\n\n    [mkdir] Created dir: C:\\Projects\\lucene\\trunk-full1\\build\\test\n\n    [junit] Testsuite: org.apache.lucene.index.TestIndexWriter\n\n    [junit] Tests run: 102, Failures: 0, Errors: 1, Time elapsed: 100,297sec\n\n    [junit]\n\n    [junit] Testcase: testExceptionDuringSync(org.apache.lucene.index.TestIndexWriter): Caused an ERROR\n\n    [junit] _a.fnm\n\n    [junit] java.io.FileNotFoundException: _a.fnm\n\n    [junit]     at org.apache.lucene.store.MockRAMDirectory.openInput(MockRAMDirectory.java:226)\n\n    [junit]     at org.apache.lucene.index.FieldInfos.<init>(FieldInfos.java:68)\n\n    [junit]     at org.apache.lucene.index.SegmentReader$CoreReaders.<init>(SegmentReader.java:116)\n\n    [junit]     at org.apache.lucene.index.SegmentReader.get(SegmentReader.java:620)\n\n    [junit]     at org.apache.lucene.index.SegmentReader.get(SegmentReader.java:590)\n\n    [junit]     at org.apache.lucene.index.DirectoryReader.<init>(DirectoryReader.java:104)\n\n    [junit]     at org.apache.lucene.index.ReadOnlyDirectoryReader.<init>(ReadOnlyDirectoryReader.java:27)\n\n    [junit]     at org.apache.lucene.index.DirectoryReader$1.doBody(DirectoryReader.java:74)\n\n    [junit]     at org.apache.lucene.index.SegmentInfos$FindSegmentsFile.run(SegmentInfos.java:704)\n\n    [junit]     at org.apache.lucene.index.DirectoryReader.open(DirectoryReader.java:69)\n\n    [junit]     at org.apache.lucene.index.IndexReader.open(IndexReader.java:307)\n\n    [junit]     at org.apache.lucene.index.IndexReader.open(IndexReader.java:193)\n\n    [junit]     at org.apache.lucene.index.TestIndexWriter.testExceptionDuringSync(TestIndexWriter.java:2723)\n\n    [junit]     at org.apache.lucene.util.LuceneTestCase.runBare(LuceneTestCase.java:206)\n\n    [junit]\n\n    [junit]\n\n    [junit] Test org.apache.lucene.index.TestIndexWriter FAILED",
    "attachments": {
        "LUCENE-1992.patch": "https://issues.apache.org/jira/secure/attachment/12422514/LUCENE-1992.patch"
    },
    "issue_links": {},
    "comments": [
        {
            "date": "2009-10-18T23:41:22+0000",
            "content": "Patch attached.  I'll commit shortly on trunk & 2.9.1.\n\nThere is a thread hazard that happens when a merge is committing just\nas an exception is happening during sync.  There merge actually\nchanges the segmentInfos, but fails to checkpoint before exiting the\nsync block.  If an exception during syncing is handled in another\nthread, this can then decRef the newly merged segment to 0, deleting\nit too early. ",
            "author": "Michael McCandless",
            "id": "comment-12767162"
        },
        {
            "date": "2009-10-18T23:46:07+0000",
            "content": "Thanks for reporting this Uwe! ",
            "author": "Michael McCandless",
            "id": "comment-12767164"
        },
        {
            "date": "2009-10-19T06:23:07+0000",
            "content": "From the patch:\n\n-    // We expect sync exceptions in the merge threads\n-    cms.setSuppressExceptions();\n\n\n\nShould this also applied to bw branch (2.4 for) 2.9 and (2.9 for) 3.0? I do not know what this call really does and what effect it has. ",
            "author": "Uwe Schindler",
            "id": "comment-12767223"
        },
        {
            "date": "2009-10-19T09:25:55+0000",
            "content": "Should this also applied to bw branch (2.4 for) 2.9 and (2.9 for) 3.0? \n\nNo, it can only be applied on trunk.\n\nThat call tells ConcurrentMergeScheduler to expect exceptions during this test, which when autoCommit is true (which this test is doing everywhere except trunk) will happen because when a merge completes, it'll commit and call Directory.sync which throws the intentional exception. ",
            "author": "Michael McCandless",
            "id": "comment-12767258"
        },
        {
            "date": "2009-11-07T14:57:30+0000",
            "content": "Bulk close all 2.9.1 issues. ",
            "author": "Michael McCandless",
            "id": "comment-12774618"
        }
    ]
}