{
    "id": "SOLR-6269",
    "title": "Change \"rollback\" to \"error\" in DIH",
    "details": {
        "affect_versions": "4.9",
        "status": "Resolved",
        "fix_versions": [
            "4.10",
            "6.0"
        ],
        "components": [
            "contrib - DataImportHandler"
        ],
        "type": "Bug",
        "priority": "Major",
        "labels": "",
        "resolution": "Fixed"
    },
    "description": "Since rollback (see SOLR-3622) is going away from DIH, at least in SolrCloud mode, let's rename most things \"rollback\" to \"error\", such as the new onRollback handler.",
    "attachments": {
        "SOLR-6269.patch": "https://issues.apache.org/jira/secure/attachment/12657354/SOLR-6269.patch"
    },
    "issue_links": {},
    "comments": [
        {
            "author": "Erik Hatcher",
            "id": "comment-14071760",
            "date": "2014-07-23T14:14:19+0000",
            "content": "attached patch for trunk.  This patch avoids calling the Solr rollback capability when in ZK mode (maybe this should be a tackled separately though) "
        },
        {
            "author": "Noble Paul",
            "id": "comment-14071764",
            "date": "2014-07-23T14:19:20+0000",
            "content": "Let's change this entity level onError to be an eventHandler which can be a java class or javascript function.\n\nChange the signature of EventListener.onEvent(..) to return an Object\n\nIf the listener is implemented , it should return one of ABORT|CONTINUE|SKIP\n\nAs of now it is an entity level attribute and we can leave it as it is\n\nThe ctx.getLastException() should give the actual exception that happened\n\n "
        },
        {
            "author": "Erik Hatcher",
            "id": "comment-14071791",
            "date": "2014-07-23T14:38:13+0000",
            "content": "I think we should leave the entity level modifications to another ticket.\n\nNoble Paul What do you mean that lastException should give the actual exception that happened?   Is that different than what's in my patch (other than a getter for the internal value could be added)?   Is there a different exception that should be captured before this handler is called? "
        },
        {
            "author": "ASF subversion and git services",
            "id": "comment-14074335",
            "date": "2014-07-25T12:21:06+0000",
            "content": "Commit 1613406 from Erik Hatcher in branch 'dev/trunk'\n[ https://svn.apache.org/r1613406 ]\n\nSOLR-3622, SOLR-5847, SOLR-6194, SOLR-6269: Several DIH fixes/improvements "
        },
        {
            "author": "ASF subversion and git services",
            "id": "comment-14074340",
            "date": "2014-07-25T12:25:47+0000",
            "content": "Commit 1613409 from Erik Hatcher in branch 'dev/branches/branch_4x'\n[ https://svn.apache.org/r1613409 ]\n\nSOLR-3622, SOLR-5847, SOLR-6194, SOLR-6269: Several DIH fixes/improvements (merged from r1613406) "
        },
        {
            "author": "Noble Paul",
            "id": "comment-14074347",
            "date": "2014-07-25T12:32:31+0000",
            "content": "I just went  through the patch\nIt's fine.  "
        }
    ]
}